Workbook

Sheet Summary
A1: YukthiX product tracker
A2: Generated 2026-10-07 from docs/yukthix (design docs, roadmap, go-live) and the code in: exam-app-org, exam-app-ws
A4: Design rules
A5: Built + tested | B5: =COUNTIF(Rules!$H$2:$H$982,"Built + tested")
A6: Built, no test cites it | B6: =COUNTIF(Rules!$H$2:$H$982,"Built, no test cites it")
A7: Tested, code not linked | B7: =COUNTIF(Rules!$H$2:$H$982,"Tested, code not linked")
A8: UI prototype only | B8: =COUNTIF(Rules!$H$2:$H$982,"UI prototype only")
A9: Verify (step done, not linked) | B9: =COUNTIF(Rules!$H$2:$H$982,"Verify (step done, not linked)")
A10: In progress | B10: =COUNTIF(Rules!$H$2:$H$982,"In progress")
A11: Not started | B11: =COUNTIF(Rules!$H$2:$H$982,"Not started")
A12: Not needed | B12: =COUNTIF(Rules!$H$2:$H$982,"Not needed")
A13: All rules | B13: =COUNTA(Rules!$A$2:$A$982)
A14: % built + tested | B14: =COUNTIF(Rules!$H$2:$H$982,"Built + tested")/COUNTA(Rules!$A$2:$A$982)
A16: Work
A17: Open work items not done | B17: =COUNTA('Open work'!A2:A16)-COUNTIF('Open work'!E2:E16,"Done")
A18: Deferred items still open | B18: =COUNTA(Deferred!A2:A106)-COUNTIF(Deferred!G2:G106,"Done")-COUNTIF(Deferred!G2:G106,"Accepted*")-COUNTIF(Deferred!G2:G106,"Moved*")
A19: Go-live items not done | B19: =COUNTA('Go-live'!A2:A13)-COUNTIF('Go-live'!F2:F13,"Done")
A21: UI
A22: Screen files | B22: 102
A23: Screen files wired to the API | B23: 23
A24: Storybook stories | B24: 2975
A26: Design
A27: Design docs | B27: 52
A28: PRs (YukthiX branches) | B28: 4
A30: Backlog
A31: Epics | B31: =COUNTIF(Backlog!$C$2:$C$1564,"Epic")
A32: Features | B32: =COUNTIF(Backlog!$C$2:$C$1564,"Feature")
A33: Stories | B33: =COUNTIF(Backlog!$C$2:$C$1564,"Story")
A34: Stories Done | B34: =COUNTIFS(Backlog!$C$2:$C$1564,"Story",Backlog!$I$2:$I$1564,"Done")
A35: Stories Active | B35: =COUNTIFS(Backlog!$C$2:$C$1564,"Story",Backlog!$I$2:$I$1564,"Active")
A36: Stories New | B36: =COUNTIFS(Backlog!$C$2:$C$1564,"Story",Backlog!$I$2:$I$1564,"New")
A37: Story points total | B37: =SUMIFS(Backlog!$K$2:$K$1564,Backlog!$C$2:$C$1564,"Story")
A38: % points done | B38: =SUMIFS(Backlog!$K$2:$K$1564,Backlog!$C$2:$C$1564,"Story",Backlog!$I$2:$I$1564,"Done")/SUMIFS(Backlog!$K$2:$K$1564,Backlog!$C$2:$C$1564,"Story")
A39: Rules not covered by a story | B39: =COUNTA(Coverage!A2:A1031)
A42: How to read this
A43: Rules: every YX-... rule in the design docs. "Built + tested" means a code file and a test file cite the rule ID.
A44: "Verify" means its roadmap step is done but no code or test cites the rule: confirm it is built and add the ID to its test, or build it.
A45: Override (you) on the Rules sheet replaces the automatic status (e.g. "Not needed" with a note).
A46: Deferred: things each build job reported as left out. Close, move to a step, or accept each one.
A47: Columns marked (you) are kept when the tracker is regenerated. Everything else is rebuilt from the docs and the code.
...

Sheet Rules
A1: Rule ID | B1: Doc | C1: Area | D1: Roadmap step | E1: Rule (from the design doc) | F1: Status (auto) | G1: Override (you) | H1: Status | I1: Code files | J1: Test files | K1: UI files | L1: Where (first 3) | M1: Notes (you)
A2: YX-ORG-23 | B2: APX-E | C2: YX-ORG | D2: 6+ | E2: Setup hub. Setup steps are registered in code per module with card, required / optional flag, dependencies, a computed completion check, the starter keys they apply and the editor they open; the hub shows one card per area for the products the tenant has switched on. Starter templates are applied when a product or wave is switched on, each labelled "YukthiX starter — edit for your company" and recorded in starter_applications; a starter flagged ⚑ stays "unreviewed" until a person keeps or edits it, and later YukthiX starter versions never overwrite a company value. | F2: Not started | H2: =IF(G2<>"",G2,F2) | I2: 0 | J2: 0 | K2: 0
A3: YX-ORG-24 | B3: APX-E | C3: YX-ORG | D3: 6+ | E3: Go-live readiness. Each module has registered readiness checks, each blocking or advisory (§2). A module's employee-facing features (self-service requests, mobile invites, employee notifications for that module) are switched on for a legal entity only when all its blocking checks pass and the module owner has signed off; admins can configure and test before. Sign-off records the owner, time, readiness score and an acknowledgement note for every open advisory; it cannot be given while a blocking check fails. After go-live the checks keep running as health checks and a regression alerts the owne | F3: Not started | H3: =IF(G3<>"",G3,F3) | I3: 0 | J3: 0 | K3: 0
A4: YX-ORG-25 | B4: APX-E | C4: YX-ORG | D4: 6+ | E4: Every company policy has an editor. Every setting key and policy record registered by a module declares its editor screen, Settings group, allowed scopes, dated flag and either a starter template or a P07 legal source; a CI check fails the build if a registered policy key has no editor route or no starter / legal source. Legal values (P07) are shown read-only with source and version and are never starters (spec D17). | F4: Not started | H4: =IF(G4<>"",G4,F4) | I4: 0 | J4: 0 | K4: 0
A5: YX-DOC-20 | B5: APX-F | C5: YX-DOC | D5: 6+ | E5: Starter library. Every template in this library ships as a versioned starter template labelled "YukthiX starter — edit for your company" in the template list and editor (never printed on issued documents). The company edits a copy; a later YukthiX starter version never overwrites a company-edited template and is offered as "new starter version available" with a diff. Issuing from a starter that nobody has reviewed shows the issuer a one-time warning and counts as an advisory readiness finding (APX-E YX-ORG-24). | F5: Not started | H5: =IF(G5<>"",G5,F5) | I5: 0 | J5: 0 | K5: 0
A6: YX-DOC-21 | B6: APX-F | C6: YX-DOC | D6: 6+ | E6: Restricted-area letters on the verify page. Letters issued from a restricted-area case (POSH, disciplinary, grievance, whistleblower; P02) keep QR verification on by default (P05 Q5), but the public verify page shows the letter type only as "Confidential HR letter", with company, name, date and current / superseded status; the case type never appears outside the app. | F6: Not started | H6: =IF(G6<>"",G6,F6) | I6: 0 | J6: 0 | K6: 0
A7: YX-DOC-22 | B7: APX-F | C7: YX-DOC | D7: 6+ | E7: Legally mandatory content is locked. For templates whose content is prescribed by law (statutory forms, GST tax invoice and credit note, wage slip / payslip, legally required notice wording) the editor locks the mandatory fields and blocks; the company may change branding, layout of non-mandatory parts, optional fields and language. A template cannot be activated when a mandatory field is missing (extends YX-DOC-15); the mandatory field list comes from P07 and changes with it. | F7: Not started | H7: =IF(G7<>"",G7,F7) | I7: 0 | J7: 0 | K7: 0
A8: YX-EMP-01 | B8: M01 | C8: YX-EMP | D8: 2 | E8: Identity fields are validated on entry (PAN format + verification, Aadhaar checksum, UAN/ESIC/IFSC formats); Aadhaar is stored encrypted and displayed masked (P02 YX-SEC-08). | F8: Built + tested | H8: =IF(G8<>"",G8,F8) | I8: 1 | J8: 2 | K8: 2 | L8: exam-app-org:apps/api/src/access/scope.spec.ts exam-app-org:apps/api/src/people/profile.dto.ts exam-app-org:apps/api/test/access-privacy.e2e-spec.ts
A9: YX-EMP-02 | B9: M01 | C9: YX-EMP | D9: 2 | E9: Duplicate PAN, Aadhaar or salary bank account across active employees raises a blocking warning with the conflicting record (HR may override with reason). | F9: Built + tested | H9: =IF(G9<>"",G9,F9) | I9: 4 | J9: 2 | K9: 2 | L9: exam-app-org:apps/api/prisma/migrations/20261010000000_access_privacy/migration.sql exam-app-org:apps/api/prisma/schema.prisma exam-app-org:apps/api/src/people/profile.dto.ts
A10: YX-EMP-03 | B10: M01 | C10: YX-EMP | D10: 2 | E10: Custom fields carry a sensitivity class and self-edit flag; P02 rules apply to them like built-in fields. | F10: Verify (step done, not linked) | H10: =IF(G10<>"",G10,F10) | I10: 0 | J10: 0 | K10: 0
A11: YX-EMP-04 | B11: M01 | C11: YX-EMP | D11: 2 | E11: Dotted-line managers never enter approval chains unless a policy explicitly names them. | F11: Built + tested | H11: =IF(G11<>"",G11,F11) | I11: 3 | J11: 2 | K11: 1 | L11: exam-app-org:apps/api/prisma/migrations/20261009000000_people_core/migration.sql exam-app-org:apps/api/prisma/schema.prisma exam-app-org:apps/api/src/employee-history/history-rules.ts
A12: YX-EMP-05 | B12: M01 | C12: YX-EMP | D12: 2 | E12: Every job change is a P06 change with a type, impact preview, approval and (where configured) a letter; a promotion that changes pay updates compensation in the same change. | F12: Verify (step done, not linked) | H12: =IF(G12<>"",G12,F12) | I12: 0 | J12: 0 | K12: 0
A13: YX-EMP-06 | B13: M01 | C13: YX-EMP | D13: 2 | E13: Long absence (sabbatical, long LWP, maternity, long-term disability) is a dated absence status on the employment with an expected return date; starting, changing and ending it are P06 changes, the return fires return-to-work tasks, and its payroll / leave / statutory effects come from M02 / M03. Sabbatical eligibility, length and pay are company policy (starter template). | F13: Verify (step done, not linked) | H13: =IF(G13<>"",G13,F13) | I13: 0 | J13: 0 | K13: 0
A14: YX-EMP-07 | B14: M01 | C14: YX-EMP | D14: 2 | E14: An assignment with host fields takes its holiday calendar, PT state and geofence from the host location for the assignment's dates while the home entity stays the employer; a recharge flag lists it in the recharge report. Bulk restructures use one wizard with YX-ORG-17 options as editable defaults; an entity is closed only when it has no active employments and its last payroll period is locked. | F14: Verify (step done, not linked) | H14: =IF(G14<>"",G14,F14) | I14: 0 | J14: 0 | K14: 0
A15: YX-EMP-08 | B15: M01 | C15: YX-EMP | D15: 2 | E15: Every inter-entity transfer opens a continuity checklist (UAN transfer, ESI IP, Form 12B into the new entity, declarations / proofs, loans re-parented when "no F&F", leave-ledger transfer entries, gratuity exemption carried across payouts); open items are visible on the change and in M03 pre-flight. | F15: Verify (step done, not linked) | H15: =IF(G15<>"",G15,F15) | I15: 0 | J15: 0 | K15: 0
A16: YX-EMP-09 | B16: M01 | C16: YX-EMP | D16: 2 | E16: Positions (B16): in position-based mode every assignment references a position of the same entity; the sum of incumbents' FTE never exceeds the position's FTE (job-share allowed); creating, re-grading or closing a position is a P03 request; a position becomes vacant on its incumbent's exit or transfer and "Open requisition" on a vacant / approved position creates an M10 requisition linked to it and its plan line; in job-based mode (starter) positions are optional and nothing is blocked. | F16: Verify (step done, not linked) | H16: =IF(G16<>"",G16,F16) | I16: 0 | J16: 0 | K16: 0
A17: YX-EMP-10 | B17: M01 | C17: YX-EMP | D17: 2 | E17: Workforce scenarios (B16): a scenario never changes live data; its forecast = current headcount and cost ± planned changes, reduced by the scenario's attrition rate per department with backfill lag; costs use M03 compensation and employer contributions (new hires at band midpoint); only an approved scenario (P03) creates positions / M10 headcount-plan lines; scenarios are Confidential (HR, finance, leadership). | F17: Verify (step done, not linked) | H17: =IF(G17<>"",G17,F17) | I17: 0 | J17: 0 | K17: 0
A18: YX-EMP-11 | B18: M01 | C18: YX-EMP | D18: 2 | E18: Career paths & IDPs (B16) — owned by M06. Rules are YX-PERF-14 (IDP) and YX-PERF-15 (career paths); M01 only displays them (Me › Career, succession view) and never keeps its own copy. | F18: Verify (step done, not linked) | H18: =IF(G18<>"",G18,F18) | I18: 0 | J18: 0 | K18: 0
A19: YX-EMP-12 | B19: M01 | C19: YX-EMP | D19: 2 | E19: Attrition-risk signal (B16) — owned by M06. Rules are YX-PERF-17 (HR only, advisory, never read by any workflow, approval, rating, pay, notification or selection step). M01 workforce scenarios (YX-EMP-10) use only the aggregate P09 attrition rate, never individual bands. | F19: Verify (step done, not linked) | H19: =IF(G19<>"",G19,F19) | I19: 0 | J19: 0 | K19: 0
A20: YX-EMP-13 | B20: M01 | C20: YX-EMP | D20: 2 | E20: Annual health check-up (C1): where P07 IN.OSH prescribes it, eligible workers (currently aged 40+) are listed yearly per establishment, get a scheduling task and a free check-up record; outcomes and reports are Special class (P02), hidden from managers (who see scheduled / done only), and nothing is charged to the employee. | F20: Verify (step done, not linked) | H20: =IF(G20<>"",G20,F20) | I20: 0 | J20: 0 | K20: 0
A21: YX-EMP-14 | B21: M01 | C21: YX-EMP | D21: 2 | E21: Disability declaration (R8). Disability status is voluntary and recorded only with explicit, withdrawable consent; it is Special class (P02): never shown to the manager, used by payroll only as the ESI PwD ceiling flag (P07 IN.ESI), and reported only in aggregate with small-cell suppression; the equal-opportunity policy (M08, starter template) is linked from the declaration. Withdrawal hides the data from all but the audit trail within the retention rule. | F21: Verify (step done, not linked) | H21: =IF(G21<>"",G21,F21) | I21: 0 | J21: 0 | K21: 0
A22: YX-EMP-15 | B22: M01 | C22: YX-EMP | D22: 2 | E22: Union register and membership (J4). Unions, their recognition (basis and dates, per IR Code negotiating-union rules, verify) and dated employee memberships with check-off consent are kept per legal entity / establishment; membership is Confidential (P02: HR-IR role and payroll for dues only), never used by other modules; lay-off, strike and lockout days from M02 (YX-AT-27) appear on the employee timeline. | F22: Verify (step done, not linked) | H22: =IF(G22<>"",G22,F22) | I22: 0 | J22: 0 | K22: 0
A23: YX-EMP-16 | B23: M01 | C23: YX-EMP | D23: 2 | E23: Periodic re-verification (V11, T22). Re-verification runs only per a company rule (periodic N years, role change into a sensitive role, client mandate), each cycle with fresh consent via the P10 BGV connector; results are Confidential (adverse findings Special), open an HR review task, and never trigger an automatic status change. | F23: Verify (step done, not linked) | H23: =IF(G23<>"",G23,F23) | I23: 0 | J23: 0 | K23: 2
... A25: YX-EMP-18 | B25: M01 | C25: YX-EMP | D25: 2 | E25: Insider-trading designated persons (V12). Designated persons (SEBI PIT Regulations 2015, verify) file holdings and relatives disclosures on designation and yearly, and need pre-clearance for trades above the company threshold; a pre-clearance is valid for the company's window (starter 7 trading days, verify) and blocked during a trading-window closure; the trade is reported back and late / missing reports alert the compliance officer. | F25: Verify (step done, not linked) | H25: =IF(G25<>"",G25,F25) | I25: 0 | J25: 0 | K25: 2
A26: YX-LC-01 | B26: M01 | C26: YX-LC | D26: 2 | E26: Probation reviews are created N days before the end; unresolved reviews escalate to HR on the end date; no auto-confirmation unless the tenant enables it. | F26: Built + tested | H26: =IF(G26<>"",G26,F26) | I26: 5 | J26: 2 | K26: 4 | L26: exam-app-org:apps/api/prisma/migrations/20261009000000_people_core/migration.sql exam-app-org:apps/api/src/jobs/scheduled-sweeps.queue.ts exam-app-org:apps/api/src/jobs/scheduled-sweeps.worker.service.ts
A27: YX-LC-02 | B27: M01 | C27: YX-LC | D27: 2 | E27: Onboarding and offboarding tasks use relative due dates (negative allowed), named owners and SLA reminders; progress is shown on the employee record. | F27: Verify (step done, not linked) | H27: =IF(G27<>"",G27,F27) | I27: 0 | J27: 0 | K27: 2
A28: YX-LC-03 | B28: M01 | C28: YX-LC | D28: 2 | E28: Pre-boarding data becomes employee data on joining without re-entry; unverified mandatory documents are flagged in payroll pre-flight (P05 YX-DOC-17). | F28: Verify (step done, not linked) | H28: =IF(G28<>"",G28,F28) | I28: 0 | J28: 0 | K28: 0
A29: YX-LC-04 | B29: M01 | C29: YX-LC | D29: 2 | E29: Resignation notice is computed from the policy valid on the submission date; early release, buy-out and withdrawal each require approval and are recorded on the exit case. | F29: Verify (step done, not linked) | H29: =IF(G29<>"",G29,F29) | I29: 0 | J29: 0 | K29: 4
A30: YX-LC-05 | B30: M01 | C30: YX-LC | D30: 2 | E30: On the last working day: access converts to alumni, implicit grants end, open approvals are reassigned and pending onboarding/exit tasks are escalated. | F30: Verify (step done, not linked) | H30: =IF(G30<>"",G30,F30) | I30: 0 | J30: 0 | K30: 0
A31: YX-LC-06 | B31: M01 | C31: YX-LC | D31: 2 | E31: F&F is calculated (not just tracked): final salary, encashment, bonus, gratuity, reimbursements, arrears, notice pay in lieu minus notice shortfall, negative leave, expense advances (M05 Q6), salary advances / loans (M03 Q4), assets, training-bond recovery (M07 Q5), joining / retention bonus clawback (M10 Q3), other, with TDS; every line is explained. | F31: Verify (step done, not linked) | H31: =IF(G31<>"",G31,F31) | I31: 0 | J31: 0 | K31: 2
A32: YX-LC-07 | B32: M01 | C32: YX-LC | D32: 2 | E32: Open expense advances (M05 Q6), salary advances / loans (M03 Q4), unreturned assets, negative leave balances, confirmed training-bond recoveries (M07 Q5) and bonus clawbacks (M10 Q3) are pulled into the F&F automatically and refreshed until the F&F is approved (fixes U65). | F32: Verify (step done, not linked) | H32: =IF(G32<>"",G32,F32) | I32: 0 | J32: 0 | K32: 2
A33: YX-LC-08 | B33: M01 | C33: YX-LC | D33: 2 | E33: F&F due dates follow the legal deadline: wages due on exit are paid within 2 working days of the LWD for every exit type (P07 IN.WAGES-CODE, from 21 Nov 2025) and other dues by their own P07 deadlines; holds, open clearance and missing payee details never move the due date (wage lines may be paid in a first F&F run); overdue settlements are flagged to HR/Payroll. *(Amended by Correction C1.)* | F33: Verify (step done, not linked) | H33: =IF(G33<>"",G33,F33) | I33: 0 | J33: 0 | K33: 4
A34: YX-LC-09 | B34: M01 | C34: YX-LC | D34: 2 | E34: Exit interview answers marked confidential are visible only to HR roles, never to the leaver's manager. | F34: Verify (step done, not linked) | H34: =IF(G34<>"",G34,F34) | I34: 0 | J34: 0 | K34: 0
A35: YX-LC-10 | B35: M01 | C35: YX-LC | D35: 2 | E35: Rehire-eligibility flags are HR-only and surface when the person reappears in the ATS. | F35: Verify (step done, not linked) | H35: =IF(G35<>"",G35,F35) | I35: 0 | J35: 0 | K35: 0
A36: YX-LC-11 | B36: M01 | C36: YX-LC | D36: 2 | E36: Onboarding branches by person type (M10 hand-off matrix): a new person gets a new employee record; an ex-employee rehire gets a new employment on the existing record (rehire_of, P01 YX-ORG-19 continuity options, pre-filled from the old record); an internal move is a P06 transfer / promotion effective on a release date agreed with the current manager, never an onboarding; a contractor conversion is a P06 employment-type change. Amended 28 Sep 2026 (J15): the person type is decided from the P01 person record (YX-ORG-26 / 27), not from the offer or name. | F36: Verify (step done, not linked) | H36: =IF(G36<>"",G36,F36) | I36: 0 | J36: 0 | K36: 0
A37: YX-LC-12 | B37: M01 | C37: YX-LC | D37: 2 | E37: A pre-boarder who did not join, reneged or whose offer was withdrawn after acceptance (manual, reason mandatory, withdrawal letter) is unwound in one audited action: employee, employment, draft compensation and pre-boarding login are cancelled (kept, not deleted), the M10 headcount-plan slot is released and the requisition reopened, and the candidate is marked reneged / withdrawn. Pre-boarders are never counted as active employees for billing. | F37: Verify (step done, not linked) | H37: =IF(G37<>"",G37,F37) | I37: 0 | J37: 0 | K37: 0
A38: YX-LC-13 | B38: M01 | C38: YX-LC | D38: 2 | E38: Changing a pre-boarder's joining date re-anchors the journey: every open task's due date, the draft compensation, the assignment start and the probation dates move with the new joining date; completed tasks are untouched. | F38: Verify (step done, not linked) | H38: =IF(G38<>"",G38,F38) | I38: 0 | J38: 0 | K38: 2
... A61: YX-AT-03 | B61: M02 | C61: YX-AT | D61: 4 | E61: Day status is derived by the day engine; a missing punch yields "missing check-in/out", never a threshold-based status. | F61: Not started | H61: =IF(G61<>"",G61,F61) | I61: 0 | J61: 0 | K61: 0
A62: YX-AT-04 | B62: M02 | C62: YX-AT | D62: 4 | E62: Overtime counts only beyond the policy minimum, rounded down to the policy unit, capped per P07 statutory limits, and reaches payroll only when approved (Q7). | F62: Tested, code not linked | H62: =IF(G62<>"",G62,F62) | I62: 0 | J62: 2 | K62: 2 | L62: exam-app-org:packages/yx-ui/src/screens/time/time.test.tsx exam-app-ws:packages/yx-ui/src/screens/time/time.test.tsx
A63: YX-AT-05 | B63: M02 | C63: YX-AT | D63: 4 | E63: Late penalties follow the tenant's policy (Q4) and appear on the day card and muster before they affect pay. | F63: Not started | H63: =IF(G63<>"",G63,F63) | I63: 0 | J63: 0 | K63: 0
...

Sheet Design docs
A1: Doc | B1: Title | C1: Roadmap step | D1: Rules | E1: Built + tested | F1: Built, no test | G1: Verify | H1: Not started | I1: % built | J1: Build wave | K1: Design status | L1: File | M1: Notes (you)
A2: M01 | B2: M01 · Core HR & Employee Lifecycle | C2: 2 | D2: 51 | E2: =COUNTIFS(Rules!$B$2:$B$982,$A2,Rules!$H$2:$H$982,"Built +*") | F2: =COUNTIFS(Rules!$B$2:$B$982,$A2,Rules!$H$2:$H$982,"Built,*") | G2: =COUNTIFS(Rules!$B$2:$B$982,$A2,Rules!$H$2:$H$982,"Verify*") | H2: =COUNTIFS(Rules!$B$2:$B$982,$A2,Rules!$H$2:$H$982,"Not started*") | I2: =IF(D2=0,"",E2/D2) | J2: Core HR in wave 1; onboarding, offboarding, F&F, letters, assets in wave 4 (spec §4). | K2: ✅ Decided, 25 Sep 2026. All 8 questions answered (§11). Extended 26 Sep 2026 (gap register, user decision): position management, workforce-planning scenarios, career paths & IDPs, attrition-risk signal (GAP B16, §3.9, wave 5); §11 B16. Career paths, IDPs, talent pools and the attrition-risk signal a | L2: M01-core-hr-and-lifecycle.md
A3: M02 | B3: M02 · Leave & Attendance | C3: 4 | D3: 46 | E3: =COUNTIFS(Rules!$B$2:$B$982,$A3,Rules!$H$2:$H$982,"Built +*") | F3: =COUNTIFS(Rules!$B$2:$B$982,$A3,Rules!$H$2:$H$982,"Built,*") | G3: =COUNTIFS(Rules!$B$2:$B$982,$A3,Rules!$H$2:$H$982,"Verify*") | H3: =COUNTIFS(Rules!$B$2:$B$982,$A3,Rules!$H$2:$H$982,"Not started*") | I3: =IF(D3=0,"",E3/D3) | J3: 2 (with basic mobile), feeding payroll in wave 3. | K3: ✅ Decided (7/7), 25 Sep 2026. The 6 Leave decisions (23 Sep) and the attendance device question (P10 Q4) are already decided. Extended 26 Sep 2026 (gap register, user decision): field-force tracking (GAP B2, §B8, wave 5), auto-rostering, open shifts & shift bidding (GAP B3, §B9, designed now, built | L3: M02-leave-and-attendance.md
A4: M03 | B4: M03 · Payroll & India Statutory | C4: 5 | D4: 84 | E4: =COUNTIFS(Rules!$B$2:$B$982,$A4,Rules!$H$2:$H$982,"Built +*") | F4: =COUNTIFS(Rules!$B$2:$B$982,$A4,Rules!$H$2:$H$982,"Built,*") | G4: =COUNTIFS(Rules!$B$2:$B$982,$A4,Rules!$H$2:$H$982,"Verify*") | H4: =COUNTIFS(Rules!$B$2:$B$982,$A4,Rules!$H$2:$H$982,"Not started*") | I4: =IF(D4=0,"",E4/D4) | J4: 3. The private pilot starts here. | K4: ✅ Decided (8/8), 25 Sep 2026. Extended 26 Sep 2026: consultant / contractor payouts (GAP A8) and always-on digital registers (GAP A9), §11 A8-Q1 / A9-Q2 / A9-Q3. Extended 26 Sep 2026 (gap register, user decision): earned wage access (GAP B10), multi-country payroll readiness with UAE / GCC / US-1099 | L4: M03-payroll-and-statutory.md
A5: M04 | B5: M04 · Mobile App (Employee & Manager) | C5: 6+ | D5: 19 | E5: =COUNTIFS(Rules!$B$2:$B$982,$A5,Rules!$H$2:$H$982,"Built +*") | F5: =COUNTIFS(Rules!$B$2:$B$982,$A5,Rules!$H$2:$H$982,"Built,*") | G5: =COUNTIFS(Rules!$B$2:$B$982,$A5,Rules!$H$2:$H$982,"Verify*") | H5: =COUNTIFS(Rules!$B$2:$B$982,$A5,Rules!$H$2:$H$982,"Not started*") | I5: =IF(D5=0,"",E5/D5) | J5: basic mobile in wave 2 (Time, leave, approvals), and each later module adds its mobile screens in its own wave. No module ships without its employee-facing mobile flow (fixes U95). | K5: ✅ Decided (8/8), 25 Sep 2026. Extended 26 Sep 2026 (gap register, user decision): mobile flows for field force (B2), open shifts & bids (B3), earned wage access (B10), visitor approvals (C1), career / IDP (B16), equity (C4) and M12 timesheets (B1), §3.1; §11 B2 / B3 / B10 / C1 / B1 / B16-C4-B18. Val | L5: M04-mobile-app.md
A6: M05 | B6: M05 · Expenses, Advances & Travel | C6: 6+ | D6: 16 | E6: =COUNTIFS(Rules!$B$2:$B$982,$A6,Rules!$H$2:$H$982,"Built +*") | F6: =COUNTIFS(Rules!$B$2:$B$982,$A6,Rules!$H$2:$H$982,"Built,*") | G6: =COUNTIFS(Rules!$B$2:$B$982,$A6,Rules!$H$2:$H$982,"Verify*") | H6: =COUNTIFS(Rules!$B$2:$B$982,$A6,Rules!$H$2:$H$982,"Not started*") | I6: =IF(D6=0,"",E6/D6) | J6: 5 (mobile-first, M04). Salary advances and loans stay in M03. | K6: ✅ Decided (8/8), 25 Sep 2026. Extended 26 Sep 2026 (gap register, user decision): multi-currency expenses with FX (GAP B18) and field-force distance → mileage lines (GAP B2, M02 §B8); §11 B18 / B2. | L6: M05-expenses-advances-travel.md
A7: M06 | B7: M06 · Performance | C7: 6+ | D7: 22 | E7: =COUNTIFS(Rules!$B$2:$B$982,$A7,Rules!$H$2:$H$982,"Built +*") | F7: =COUNTIFS(Rules!$B$2:$B$982,$A7,Rules!$H$2:$H$982,"Built,*") | G7: =COUNTIFS(Rules!$B$2:$B$982,$A7,Rules!$H$2:$H$982,"Verify*") | H7: =COUNTIFS(Rules!$B$2:$B$982,$A7,Rules!$H$2:$H$982,"Not started*") | I7: =IF(D7=0,"",E7/D7) | J7: 5. Basic (guided) calibration was deliberately moved to wave 5 by Q5; only the 9-box and enforced distribution remain in wave 6 (spec §4). | K7: ✅ Decided (8/8), 25 Sep 2026. Extended 26 Sep 2026: career paths & IDPs, talent pools / succession link, attrition-risk signal (GAP B16); pay-equity analysis and compensation benchmarking (GAP C3); §11 B16 / C3. | L7: M06-performance.md
A8: M07 | B8: M07 · Learning & Development | C8: 6+ | D8: 15 | E8: =COUNTIFS(Rules!$B$2:$B$982,$A8,Rules!$H$2:$H$982,"Built +*") | F8: =COUNTIFS(Rules!$B$2:$B$982,$A8,Rules!$H$2:$H$982,"Built,*") | G8: =COUNTIFS(Rules!$B$2:$B$982,$A8,Rules!$H$2:$H$982,"Verify*") | H8: =COUNTIFS(Rules!$B$2:$B$982,$A8,Rules!$H$2:$H$982,"Not started*") | I8: =IF(D8=0,"",E8/D8) | J8: 5. | K8: ✅ Decided (8/8), 25 Sep 2026. Extended 26 Sep 2026: content marketplace & provider connectors, live-class auto-creation, gamification (GAP C2); Open Badges 3.0 / Credly and an LTI 1.3 tool (GAP B15 part); §11 C2 / B15. | L8: M07-learning-and-development.md
A9: M08 | B9: M08 · Helpdesk, Grievance, POSH, Disciplinary & Policies | C9: 3b | D9: 32 | E9: =COUNTIFS(Rules!$B$2:$B$982,$A9,Rules!$H$2:$H$982,"Built +*") | F9: =COUNTIFS(Rules!$B$2:$B$982,$A9,Rules!$H$2:$H$982,"Built,*") | G9: =COUNTIFS(Rules!$B$2:$B$982,$A9,Rules!$H$2:$H$982,"Verify*") | H9: =COUNTIFS(Rules!$B$2:$B$982,$A9,Rules!$H$2:$H$982,"Not started*") | I9: =IF(D9=0,"",E9/D9) | J9: POSH and workplace accident / injury (J6) in wave 4; helpdesk, grievance, disciplinary, policies and whistleblower in wave 5 (spec §4). | K9: ✅ Decided (8/8), 25 Sep 2026. Correction C1 (validation pass 3), 28 Sep 2026: IR Code (P07 IN.IR, in force 21 Nov 2025) Grievance Redressal Committee for 20+ workers and standing orders at 300+ workers linked to the misconduct matrix (YX-CASE-12/13); §11 C1. Validation pass 3 Must J6, 28 Sep 2026: n | L9: M08-helpdesk-cases-policies.md
A10: M09 | B10: M09 · Engage: Communication, Recognition & Surveys | C10: 6+ | D10: 11 | E10: =COUNTIFS(Rules!$B$2:$B$982,$A10,Rules!$H$2:$H$982,"Built +*") | F10: =COUNTIFS(Rules!$B$2:$B$982,$A10,Rules!$H$2:$H$982,"Built,*") | G10: =COUNTIFS(Rules!$B$2:$B$982,$A10,Rules!$H$2:$H$982,"Verify*") | H10: =COUNTIFS(Rules!$B$2:$B$982,$A10,Rules!$H$2:$H$982,"Not started*") | I10: =IF(D10=0,"",E10/D10) | J10: 5. Simple announcements already ship with P04 in wave 1. | K10: ✅ Decided (8/8), 25 Sep 2026. | L10: M09-engage.md
A11: M10 | B11: M10 · ATS: Internal Hiring, Staffing Desk & Client Helpdesk | C11: 6+ | D11: 45 | E11: =COUNTIFS(Rules!$B$2:$B$982,$A11,Rules!$H$2:$H$982,"Built +*") | F11: =COUNTIFS(Rules!$B$2:$B$982,$A11,Rules!$H$2:$H$982,"Built,*") | G11: =COUNTIFS(Rules!$B$2:$B$982,$A11,Rules!$H$2:$H$982,"Verify*") | H11: =COUNTIFS(Rules!$B$2:$B$982,$A11,Rules!$H$2:$H$982,"Not started*") | I11: =IF(D11=0,"",E11/D11) | J11: 7, after HRMS wave 5 (spec §4, P2-6). The internal ATS already exists in the exam app. This doc defines the deltas: what we keep, what we change so it becomes part of HRMS, and what is new. | K11: ✅ Decided (8/8), 25 Sep 2026. Extended 26 Sep 2026: talent CRM, job-board connectors and panel auto-slotting (GAP B8); vendor / sub-vendor portal for the staffing desk (GAP C7, reversing the spec's "out of scope"); §11 B8 / C7. Validation pass 3 Must (T10), founder decision 28 Sep 2026: identity cha | L11: M10-ats.md
A12: M11 | B12: M11 · Benefits Administration & Flexible Benefit Plan | C12: 6+ | D12: 11 | E12: =COUNTIFS(Rules!$B$2:$B$982,$A12,Rules!$H$2:$H$982,"Built +*") | F12: =COUNTIFS(Rules!$B$2:$B$982,$A12,Rules!$H$2:$H$982,"Built,*") | G12: =COUNTIFS(Rules!$B$2:$B$982,$A12,Rules!$H$2:$H$982,"Verify*") | H12: =COUNTIFS(Rules!$B$2:$B$982,$A12,Rules!$H$2:$H$982,"Not started*") | I12: =IF(D12=0,"",E12/D12) | J12: 3 (with payroll, for the pilot). Insurer / broker connectors can follow in a later wave. | K12: ✅ Decided (5/5), 26 Sep 2026. | L12: M11-benefits-fbp.md
A13: M12 | B13: M12 · Projects & Timesheets | C13: 6+ | D13: 17 | E13: =COUNTIFS(Rules!$B$2:$B$982,$A13,Rules!$H$2:$H$982,"Built +*") | F13: =COUNTIFS(Rules!$B$2:$B$982,$A13,Rules!$H$2:$H$982,"Built,*") | G13: =COUNTIFS(Rules!$B$2:$B$982,$A13,Rules!$H$2:$H$982,"Verify*") | H13: =COUNTIFS(Rules!$B$2:$B$982,$A13,Rules!$H$2:$H$982,"Not started*") | I13: =IF(D13=0,"",E13/D13) | J13: 5. | K13: ✅ Decided (by principle), 26 Sep 2026. The user decided on 26 Sep 2026 to include GAP-REGISTER B1; the 4 design questions (§10) were settled by principle (D17 / D18) with the recommended options (§11). Validation pass 3 Shoulds added 28 Sep 2026 (§8b). | L13: M12-projects-timesheets.md
A14: M13 | B14: M13 · Contract Labour (CLRA) — Principal-Employer Compliance | C14: 6+ | D14: 15 | E14: =COUNTIFS(Rules!$B$2:$B$982,$A14,Rules!$H$2:$H$982,"Built +*") | F14: =COUNTIFS(Rules!$B$2:$B$982,$A14,Rules!$H$2:$H$982,"Built,*") | G14: =COUNTIFS(Rules!$B$2:$B$982,$A14,Rules!$H$2:$H$982,"Verify*") | H14: =COUNTIFS(Rules!$B$2:$B$982,$A14,Rules!$H$2:$H$982,"Not started*") | I14: =IF(D14=0,"",E14/D14) | J14: 5. | K14: ✅ Decided (by principle), 26 Sep 2026. 4 questions decided by principle (D17 / D18), §11. Correction C1 (validation pass 3), 28 Sep 2026: contract labour is governed by the OSH Code (contract-labour chapter) since 21 Nov 2025; the design maps to it (§1 mapping, YX-CLRA-13); §11 C1. Validation pass 3 | L14: M13-contract-labour-clra.md
A15: M14 | B15: M14 · YukthiX Service Desk (ITSM + ESM) | C15: 3b | D15: 0 | E15: =COUNTIFS(Rules!$B$2:$B$982,$A15,Rules!$H$2:$H$982,"Built +*") | F15: =COUNTIFS(Rules!$B$2:$B$982,$A15,Rules!$H$2:$H$982,"Built,*") | G15: =COUNTIFS(Rules!$B$2:$B$982,$A15,Rules!$H$2:$H$982,"Verify*") | H15: =COUNTIFS(Rules!$B$2:$B$982,$A15,Rules!$H$2:$H$982,"Not started*") | I15: =IF(D15=0,"",E15/D15) | K15: 📝 Scope agreed with the founder, 6 Oct 2026. Detailed design (rules, data model, decisions) to be written before the build, in the same format as the other M docs. | L15: M14-itsm-service-desk.md
A16: P01 | B16: P01 · Tenancy & Organisation Model | C16: 0, 2 | D16: 27 | E16: =COUNTIFS(Rules!$B$2:$B$982,$A16,Rules!$H$2:$H$982,"Built +*") | F16: =COUNTIFS(Rules!$B$2:$B$982,$A16,Rules!$H$2:$H$982,"Built,*") | G16: =COUNTIFS(Rules!$B$2:$B$982,$A16,Rules!$H$2:$H$982,"Verify*") | H16: =COUNTIFS(Rules!$B$2:$B$982,$A16,Rules!$H$2:$H$982,"Not started*") | I16: =IF(D16=0,"",E16/D16) | K16: ✅ Decided, 24 Sep 2026. All 8 questions answered (§11). Validation pass 3 Must (J15), founder decision 28 Sep 2026: one persons record per tenant with role attachments, matching / merge rules, conversions with history, total-workforce view (§4.5a, YX-ORG-26 / 27); §11 J15. Validation pass 3 Shoulds | L16: P01-tenancy-and-organisation.md
A17: P02 | B17: P02 · Roles, Data Visibility & Privacy | C17: 2 | D17: 38 | E17: =COUNTIFS(Rules!$B$2:$B$982,$A17,Rules!$H$2:$H$982,"Built +*") | F17: =COUNTIFS(Rules!$B$2:$B$982,$A17,Rules!$H$2:$H$982,"Built,*") | G17: =COUNTIFS(Rules!$B$2:$B$982,$A17,Rules!$H$2:$H$982,"Verify*") | H17: =COUNTIFS(Rules!$B$2:$B$982,$A17,Rules!$H$2:$H$982,"Not started*") | I17: =IF(D17=0,"",E17/D17) | K17: ✅ Decided, 24 Sep 2026. All 8 questions answered (§11). Extended 26 Sep 2026 (gap-register user decision): DPDP / GDPR programme tooling (B12, §6.1), §11 row B12. Corrected 28 Sep 2026 (validation pass 3, C3): DPDP Rules 2025 dated milestones and readiness plan (§6.2), YX-SEC-32 breach clocks, YX-SE | L17: P02-access-visibility-privacy.md
A18: P03 | B18: P03 · Workflow & Approval Engine | C18: 4 | D18: 19 | E18: =COUNTIFS(Rules!$B$2:$B$982,$A18,Rules!$H$2:$H$982,"Built +*") | F18: =COUNTIFS(Rules!$B$2:$B$982,$A18,Rules!$H$2:$H$982,"Built,*") | G18: =COUNTIFS(Rules!$B$2:$B$982,$A18,Rules!$H$2:$H$982,"Verify*") | H18: =COUNTIFS(Rules!$B$2:$B$982,$A18,Rules!$H$2:$H$982,"Not started*") | I18: =IF(D18=0,"",E18/D18) | K18: ✅ Decided, 24 Sep 2026. All 8 questions answered (§11). | L18: P03-workflow-approval-engine.md
A19: P04 | B19: P04 · Notification Engine | C19: 1 | D19: 17 | E19: =COUNTIFS(Rules!$B$2:$B$982,$A19,Rules!$H$2:$H$982,"Built +*") | F19: =COUNTIFS(Rules!$B$2:$B$982,$A19,Rules!$H$2:$H$982,"Built,*") | G19: =COUNTIFS(Rules!$B$2:$B$982,$A19,Rules!$H$2:$H$982,"Verify*") | H19: =COUNTIFS(Rules!$B$2:$B$982,$A19,Rules!$H$2:$H$982,"Not started*") | I19: =IF(D19=0,"",E19/D19) | K19: ✅ Decided, 24 Sep 2026. All 8 questions answered (§11). Extended 26 Sep 2026 (gap-register user decision): password-protected payslip PDF by email as a company option (B19, §4.5b), Slack & Microsoft Teams apps (B9, §4.9), desk-UI internationalisation (B18 part, §4.10); §11 rows B19 / B9 / B18. | L19: P04-notification-engine.md
A20: P05 | B20: P05 · Letters, Documents & E-sign | C20: 6+ | D20: 19 | E20: =COUNTIFS(Rules!$B$2:$B$982,$A20,Rules!$H$2:$H$982,"Built +*") | F20: =COUNTIFS(Rules!$B$2:$B$982,$A20,Rules!$H$2:$H$982,"Built,*") | G20: =COUNTIFS(Rules!$B$2:$B$982,$A20,Rules!$H$2:$H$982,"Verify*") | H20: =COUNTIFS(Rules!$B$2:$B$982,$A20,Rules!$H$2:$H$982,"Not started*") | I20: =IF(D20=0,"",E20/D20) | K20: ✅ Decided, 24 Sep 2026. All 8 questions answered (§11). | L20: P05-letters-documents-esign.md
A21: P06 | B21: P06 · Effective-Dated History & Scheduled Changes | C21: 2 | D21: 15 | E21: =COUNTIFS(Rules!$B$2:$B$982,$A21,Rules!$H$2:$H$982,"Built +*") | F21: =COUNTIFS(Rules!$B$2:$B$982,$A21,Rules!$H$2:$H$982,"Built,*") | G21: =COUNTIFS(Rules!$B$2:$B$982,$A21,Rules!$H$2:$H$982,"Verify*") | H21: =COUNTIFS(Rules!$B$2:$B$982,$A21,Rules!$H$2:$H$982,"Not started*") | I21: =IF(D21=0,"",E21/D21) | K21: ✅ Decided, 25 Sep 2026. All 8 questions answered (§11). | L21: P06-effective-dated-history.md
A22: P07 | B22: P07 · Statutory Rules as Dated Data (Country Packs) | C22: 4, 5 | D22: 32 | E22: =COUNTIFS(Rules!$B$2:$B$982,$A22,Rules!$H$2:$H$982,"Built +*") | F22: =COUNTIFS(Rules!$B$2:$B$982,$A22,Rules!$H$2:$H$982,"Built,*") | G22: =COUNTIFS(Rules!$B$2:$B$982,$A22,Rules!$H$2:$H$982,"Verify*") | H22: =COUNTIFS(Rules!$B$2:$B$982,$A22,Rules!$H$2:$H$982,"Not started*") | I22: =IF(D22=0,"",E22/D22) | K22: ✅ Decided, 25 Sep 2026. All 8 questions answered (§11). Extended 26 Sep 2026: non-salary TDS (GAP A8) and IN.REGISTERS (GAP A9), §11 A8-Q1 / A9-Q2 / A9-Q3. Extended 26 Sep 2026 (gap-register user decision): labour-law advisory feed and IN.CLRA (B17, §4.3a), ESOP perquisite valuation and country-pack | L22: P07-statutory-rules-as-data.md
A23: P08 | B23: P08 · Period Locks & Audit | C23: 5 | D23: 18 | E23: =COUNTIFS(Rules!$B$2:$B$982,$A23,Rules!$H$2:$H$982,"Built +*") | F23: =COUNTIFS(Rules!$B$2:$B$982,$A23,Rules!$H$2:$H$982,"Built,*") | G23: =COUNTIFS(Rules!$B$2:$B$982,$A23,Rules!$H$2:$H$982,"Verify*") | H23: =COUNTIFS(Rules!$B$2:$B$982,$A23,Rules!$H$2:$H$982,"Not started*") | I23: =IF(D23=0,"",E23/D23) | K23: ✅ Decided, 25 Sep 2026. All 8 questions answered (§11). | L23: P08-period-locks-and-audit.md
A24: P09 | B24: P09 · Metric Layer & Analytics Platform | C24: 6+ | D24: 24 | E24: =COUNTIFS(Rules!$B$2:$B$982,$A24,Rules!$H$2:$H$982,"Built +*") | F24: =COUNTIFS(Rules!$B$2:$B$982,$A24,Rules!$H$2:$H$982,"Built,*") | G24: =COUNTIFS(Rules!$B$2:$B$982,$A24,Rules!$H$2:$H$982,"Verify*") | H24: =COUNTIFS(Rules!$B$2:$B$982,$A24,Rules!$H$2:$H$982,"Not started*") | I24: =IF(D24=0,"",E24/D24) | K24: ✅ Decided, 25 Sep 2026. All 8 questions answered (§11). Extended 26 Sep 2026 (gap register, user decision): DEI dashboard template and pay-gap metric (GAP C3), tenant-health metrics feed for customer success (C8), workforce-planning / attrition-risk metric references (B16) and AI-quality metrics (B1 | L24: P09-metric-layer-analytics.md
A25: P10 | B25: P10 · AI Layer & Integration Hub (HR additions) | C25: 6+ | D25: 27 | E25: =COUNTIFS(Rules!$B$2:$B$982,$A25,Rules!$H$2:$H$982,"Built +*") | F25: =COUNTIFS(Rules!$B$2:$B$982,$A25,Rules!$H$2:$H$982,"Built,*") | G25: =COUNTIFS(Rules!$B$2:$B$982,$A25,Rules!$H$2:$H$982,"Verify*") | H25: =COUNTIFS(Rules!$B$2:$B$982,$A25,Rules!$H$2:$H$982,"Not started*") | I25: =IF(D25=0,"",E25/D25) | K25: ✅ Decided, 25 Sep 2026. All 8 questions answered (§11). Extended 26 Sep 2026 (gap-register user decision): AI governance (B13, §A4), Slack / Teams apps (B9), external-ATS connectors (B6), earned wage access (B10), QuickBooks / Busy / Marg, mailbox sync, Aadhaar eKYC / DigiLocker (C6); §11 rows B13 / | L25: P10-ai-layer-integration-hub.md
A26: P11 | B26: P11 · API-First (Headless) Architecture | C26: 6+ | D26: 16 | E26: =COUNTIFS(Rules!$B$2:$B$982,$A26,Rules!$H$2:$H$982,"Built +*") | F26: =COUNTIFS(Rules!$B$2:$B$982,$A26,Rules!$H$2:$H$982,"Built,*") | G26: =COUNTIFS(Rules!$B$2:$B$982,$A26,Rules!$H$2:$H$982,"Verify*") | H26: =COUNTIFS(Rules!$B$2:$B$982,$A26,Rules!$H$2:$H$982,"Not started*") | I26: =IF(D26=0,"",E26/D26) | J26: the conventions start in wave 1. Every module after that ships with its API. The public developer portal opens with the pilot in wave 3. | K26: ✅ Decided (8/8), 25 Sep 2026 — TR1 (Salesforce-style extensibility) open for team review. Extended 26 Sep 2026 (gap-register user decision): custom-object APIs cross-reference to P18 (B20), YX-API-16, §11 row B20. | L26: P11-api-first-headless.md
A27: P12 | B27: P12 · Identity, Authentication & Security Programme | C27: 1 | D27: 23 | E27: =COUNTIFS(Rules!$B$2:$B$982,$A27,Rules!$H$2:$H$982,"Built +*") | F27: =COUNTIFS(Rules!$B$2:$B$982,$A27,Rules!$H$2:$H$982,"Built,*") | G27: =COUNTIFS(Rules!$B$2:$B$982,$A27,Rules!$H$2:$H$982,"Verify*") | H27: =COUNTIFS(Rules!$B$2:$B$982,$A27,Rules!$H$2:$H$982,"Not started*") | I27: =IF(D27=0,"",E27/D27) | J27: identity core in wave 1. Security programme milestones are tied to the pilot (wave 3) and public launch. | K27: ✅ Decided (8/8), 26 Sep 2026. Corrected 28 Sep 2026 (validation pass 3, C3): log retention at least 1 year (DPDP Rules 2025) and DPDP breach clocks; Q6 amended, YX-SECOPS-07 updated. Validation pass 3 Shoulds added 28 Sep 2026 (§8b). | L27: P12-identity-security.md
A28: P13 | B28: P13 · Infrastructure & Operations — brief for the engineering team | C28: 6+ | D28: 0 | E28: =COUNTIFS(Rules!$B$2:$B$982,$A28,Rules!$H$2:$H$982,"Built +*") | F28: =COUNTIFS(Rules!$B$2:$B$982,$A28,Rules!$H$2:$H$982,"Built,*") | G28: =COUNTIFS(Rules!$B$2:$B$982,$A28,Rules!$H$2:$H$982,"Verify*") | H28: =COUNTIFS(Rules!$B$2:$B$982,$A28,Rules!$H$2:$H$982,"Not started*") | I28: =IF(D28=0,"",E28/D28) | K28: ⏸ Parked for the engineering team (26 Sep 2026). The founder asked for this doc to be decided by the team, not in the product design sessions. | L28: P13-infrastructure-operations-TEAM-BRIEF.md
A29: P14 | B29: P14 · Billing, Tenant Lifecycle & Platform Console | C29: 3 | D29: 38 | E29: =COUNTIFS(Rules!$B$2:$B$982,$A29,Rules!$H$2:$H$982,"Built +*") | F29: =COUNTIFS(Rules!$B$2:$B$982,$A29,Rules!$H$2:$H$982,"Built,*") | G29: =COUNTIFS(Rules!$B$2:$B$982,$A29,Rules!$H$2:$H$982,"Verify*") | H29: =COUNTIFS(Rules!$B$2:$B$982,$A29,Rules!$H$2:$H$982,"Not started*") | I29: =IF(D29=0,"",E29/D29) | J29: billing core and tenant lifecycle before the wave-3 paid pilot. Self-serve sign-up and trial before public launch. | K29: ✅ Decided (8/8), 26 Sep 2026. Extended 26 Sep 2026 (gap register, user decision): customer-success tooling (GAP C8: health score, in-app messages to tenant admins, churn-risk alerts; §3, YX-CONSOLE-05/06, flow 6) and new partner add-ons in the catalogue (earned wage access B10, compensation benchmar | L29: P14-billing-tenant-lifecycle.md
A30: P15 | B30: P15 · Migration, Implementation & Sandbox | C30: 6+ | D30: 15 | E30: =COUNTIFS(Rules!$B$2:$B$982,$A30,Rules!$H$2:$H$982,"Built +*") | F30: =COUNTIFS(Rules!$B$2:$B$982,$A30,Rules!$H$2:$H$982,"Built,*") | G30: =COUNTIFS(Rules!$B$2:$B$982,$A30,Rules!$H$2:$H$982,"Verify*") | H30: =COUNTIFS(Rules!$B$2:$B$982,$A30,Rules!$H$2:$H$982,"Not started*") | I30: =IF(D30=0,"",E30/D30) | K30: ✅ Decided (6/6), 26 Sep 2026. Market analysis addition (G11, 26 Sep 2026): mappers for Freshteam, OrangeHRM, Horilla and a generic ATS CSV, plus a "Freshteam switch kit" page (YX-MIG-14; §11 G11). Validation pass 3 Must J3, 28 Sep 2026: month-wise as-paid pay lines per component for the current tax | L30: P15-migration-implementation-sandbox.md
A31: P16 | B31: P16 · Partner & Accountant Console | C31: 6+ | D31: 14 | E31: =COUNTIFS(Rules!$B$2:$B$982,$A31,Rules!$H$2:$H$982,"Built +*") | F31: =COUNTIFS(Rules!$B$2:$B$982,$A31,Rules!$H$2:$H$982,"Built,*") | G31: =COUNTIFS(Rules!$B$2:$B$982,$A31,Rules!$H$2:$H$982,"Verify*") | H31: =COUNTIFS(Rules!$B$2:$B$982,$A31,Rules!$H$2:$H$982,"Not started*") | I31: =IF(D31=0,"",E31/D31) | K31: ✅ Decided (6/6), 26 Sep 2026. Q5 and Q6 are decided by principle (D15 / D17). | L31: P16-partner-accountant-console.md
A32: P17 | B32: P17 · Global Search & Command Palette | C32: 6+ | D32: 12 | E32: =COUNTIFS(Rules!$B$2:$B$982,$A32,Rules!$H$2:$H$982,"Built +*") | F32: =COUNTIFS(Rules!$B$2:$B$982,$A32,Rules!$H$2:$H$982,"Built,*") | G32: =COUNTIFS(Rules!$B$2:$B$982,$A32,Rules!$H$2:$H$982,"Verify*") | H32: =COUNTIFS(Rules!$B$2:$B$982,$A32,Rules!$H$2:$H$982,"Not started*") | I32: =IF(D32=0,"",E32/D32) | J32: wave 2 (records and actions for the modules live by then); every later module registers its sources in its own wave. | K32: ✅ Decided (by principle), 26 Sep 2026. The 3 questions (§10) were decided by spec principles D17 / D18 and the user decision of 26 Sep 2026 (all B items included, recommended options adopted); see §11. | L32: P17-global-search.md
A33: P18 | B33: P18 · Custom Objects, Form & Page-Layout Builder | C33: 6+ | D33: 11 | E33: =COUNTIFS(Rules!$B$2:$B$982,$A33,Rules!$H$2:$H$982,"Built +*") | F33: =COUNTIFS(Rules!$B$2:$B$982,$A33,Rules!$H$2:$H$982,"Built,*") | G33: =COUNTIFS(Rules!$B$2:$B$982,$A33,Rules!$H$2:$H$982,"Verify*") | H33: =COUNTIFS(Rules!$B$2:$B$982,$A33,Rules!$H$2:$H$982,"Not started*") | I33: =IF(D33=0,"",E33/D33) | J33: wave 6. Custom *fields* on core entities (P01) remain wave 1; P18 adds objects, layouts and builders on top. | K33: ✅ Decided (by principle), 26 Sep 2026. The 4 questions (§10) were decided by spec principles D17 / D18 and the user decision of 26 Sep 2026 (B20 designed now, built in wave 6; recommended options adopted); see §11. | L33: P18-custom-objects-form-builder.md
A34: P19 | B34: P19 · Policy Rule Builder | C34: 6+ | D34: 14 | E34: =COUNTIFS(Rules!$B$2:$B$982,$A34,Rules!$H$2:$H$982,"Built +*") | F34: =COUNTIFS(Rules!$B$2:$B$982,$A34,Rules!$H$2:$H$982,"Built,*") | G34: =COUNTIFS(Rules!$B$2:$B$982,$A34,Rules!$H$2:$H$982,"Verify*") | H34: =COUNTIFS(Rules!$B$2:$B$982,$A34,Rules!$H$2:$H$982,"Not started*") | I34: =IF(D34=0,"",E34/D34) | K34: ✅ Decided (6/6), 26 Sep 2026. Q4–Q6 are decided by principle (D17 / D18 / P06). | L34: P19-policy-rule-builder.md
A35: P20 | B35: P20 · Growth, Trial & Customer Operations | C35: 3 | D35: 17 | E35: =COUNTIFS(Rules!$B$2:$B$982,$A35,Rules!$H$2:$H$982,"Built +*") | F35: =COUNTIFS(Rules!$B$2:$B$982,$A35,Rules!$H$2:$H$982,"Built,*") | G35: =COUNTIFS(Rules!$B$2:$B$982,$A35,Rules!$H$2:$H$982,"Verify*") | H35: =COUNTIFS(Rules!$B$2:$B$982,$A35,Rules!$H$2:$H$982,"Not started*") | I35: =IF(D35=0,"",E35/D35) | K35: ✅ Decided (5/5), 28 Sep 2026 (founder decisions on validation pass 3 Musts S1, S2, S3, S10, S11). Validation pass 3 Shoulds added 28 Sep 2026 (§8b). | L35: P20-growth-trial-customer-operations.md
A36: P21 | B36: P21 · Global Readiness | C36: 6+ | D36: 16 | E36: =COUNTIFS(Rules!$B$2:$B$982,$A36,Rules!$H$2:$H$982,"Built +*") | F36: =COUNTIFS(Rules!$B$2:$B$982,$A36,Rules!$H$2:$H$982,"Built,*") | G36: =COUNTIFS(Rules!$B$2:$B$982,$A36,Rules!$H$2:$H$982,"Verify*") | H36: =COUNTIFS(Rules!$B$2:$B$982,$A36,Rules!$H$2:$H$982,"Not started*") | I36: =IF(D36=0,"",E36/D36) | K36: ✅ Decided by founder 28 Sep 2026: design now, build before the first customer in each region (validation pass 3 Shoulds, "Global prerequisites", option A). | L36: P21-global-readiness.md
A37: P22 | B37: P22 · Workflow Studio & AI Assistant | C37: 6+ | D37: 20 | E37: =COUNTIFS(Rules!$B$2:$B$982,$A37,Rules!$H$2:$H$982,"Built +*") | F37: =COUNTIFS(Rules!$B$2:$B$982,$A37,Rules!$H$2:$H$982,"Built,*") | G37: =COUNTIFS(Rules!$B$2:$B$982,$A37,Rules!$H$2:$H$982,"Verify*") | H37: =COUNTIFS(Rules!$B$2:$B$982,$A37,Rules!$H$2:$H$982,"Not started*") | I37: =IF(D37=0,"",E37/D37) | K37: ✅ Decided (founder decisions 1–3), 28 Sep 2026. | L37: P22-workflow-studio-ai-assistant.md
A38: P23 | B38: P23 · Employee & Manager Assistants and Marketplaces | C38: 6+ | D38: 19 | E38: =COUNTIFS(Rules!$B$2:$B$982,$A38,Rules!$H$2:$H$982,"Built +*") | F38: =COUNTIFS(Rules!$B$2:$B$982,$A38,Rules!$H$2:$H$982,"Built,*") | G38: =COUNTIFS(Rules!$B$2:$B$982,$A38,Rules!$H$2:$H$982,"Verify*") | H38: =COUNTIFS(Rules!$B$2:$B$982,$A38,Rules!$H$2:$H$982,"Not started*") | I38: =IF(D38=0,"",E38/D38) | K38: ✅ Decided (founder selected these 9 features), 28 Sep 2026. | L38: P23-employee-manager-assistants-marketplaces.md
A39: T01 | B39: T01 · Question Bank & Content | C39: 6+ | D39: 17 | E39: =COUNTIFS(Rules!$B$2:$B$982,$A39,Rules!$H$2:$H$982,"Built +*") | F39: =COUNTIFS(Rules!$B$2:$B$982,$A39,Rules!$H$2:$H$982,"Built,*") | G39: =COUNTIFS(Rules!$B$2:$B$982,$A39,Rules!$H$2:$H$982,"Verify*") | H39: =COUNTIFS(Rules!$B$2:$B$982,$A39,Rules!$H$2:$H$982,"Not started*") | I39: =IF(D39=0,"",E39/D39) | K39: ✅ Decided (8/8), 25 Sep 2026. Extended 26 Sep 2026 with GAP-REGISTER B4 (job-role profiles for starter tests / JD assembly) and B14 (language proficiency and typing item types) — see §3 "Gap-register extensions" and §11. | L39: T01-question-bank.md
A40: T02 | B40: T02 · Test Builder, Adaptive Testing & Psychometrics | C40: 6+ | D40: 19 | E40: =COUNTIFS(Rules!$B$2:$B$982,$A40,Rules!$H$2:$H$982,"Built +*") | F40: =COUNTIFS(Rules!$B$2:$B$982,$A40,Rules!$H$2:$H$982,"Built,*") | G40: =COUNTIFS(Rules!$B$2:$B$982,$A40,Rules!$H$2:$H$982,"Verify*") | H40: =COUNTIFS(Rules!$B$2:$B$982,$A40,Rules!$H$2:$H$982,"Not started*") | I40: =IF(D40=0,"",E40/D40) | K40: ✅ Decided (8/8), 25 Sep 2026. Extended 26 Sep 2026 with GAP-REGISTER B4 (starter tests, JD-based assembly, sectional cut-offs) and B15 (equating across parallel forms, cut-score studies) — see §3 "Gap-register extensions" and §11. Personality / behavioural psychometrics are T06; fairness / validity | L40: T02-test-builder-adaptive.md
...

Sheet Roadmap
A1: Step | B1: What | C1: Design docs | D1: Status | E1: Rules in its docs | F1: Built + tested | G1: Notes (you)
A2: 0 | B2: PostgreSQL 17 with forced row-level security on every tenant table | C2: spec D10, P01 | D2: Done | E2: =COUNTIF(Rules!$B$2:$B$982,"P01") | F2: =COUNTIFS(Rules!$B$2:$B$982,"P01",Rules!$H$2:$H$982,"Built +*")
A3: 1 | B3: Login: sessions, lockout (company-configurable within the YukthiX floor), password floor, MFA (passkeys, TOTP, recovery codes, step-up), OTP sign-in, Google / Microsoft / SAML SSO, login and security screens | C3: P12 | D3: Done | E3: =COUNTIF(Rules!$B$2:$B$982,"P12")+COUNTIF(Rules!$B$2:$B$982,"P04") | F3: =COUNTIFS(Rules!$B$2:$B$982,"P12",Rules!$H$2:$H$982,"Built +*")+COUNTIFS(Rules!$B$2:$B$982,"P04",Rules!$H$2:$H$982,"Built +*")
A4: 1+ | B4: Generic SMS channel (any gateway by configuration; shared YukthiX account, e.g. Zoho CPaaS, plus company-owned accounts) | C4: P04 §4.4–4.5a | D4: In PR #129
A5: — | B5: Design docs and full UI prototype in the repo | C5: — | D5: PR #130
A6: 2 | B6: Organisation and employee core: legal entities, locations, departments, positions, the employee record with effective-dated history, reporting lines, roles and field-level visibility | C6: P01, P02, P06, M01 | D6: Done | E6: =COUNTIF(Rules!$B$2:$B$982,"P01")+COUNTIF(Rules!$B$2:$B$982,"P02")+COUNTIF(Rules!$B$2:$B$982,"P06")+COUNTIF(Rules!$B$2:$B$982,"M01") | F6: =COUNTIFS(Rules!$B$2:$B$982,"P01",Rules!$H$2:$H$982,"Built +*")+COUNTIFS(Rules!$B$2:$B$982,"P02",Rules!$H$2:$H$982,"Built +*")+COUNTIFS(Rules!$B$2:$B$982,"P06",Rules!$H$2:$H$982,"Built +*")+COUNTIFS(Rules!$B$2:$B$982,"M01",Rules!$H$2:$H$982,"Built +*")
A7: 3 | B7: Platform console (YukthiX staff only, same codebase, separate locked-down area): companies and lifecycle, plans and prices, shared channel accounts (move the shared SMS account here), support sessions, audit; later billing, incidents, customer success | C7: P14, P02 support sessions, P12 Q7 | D7: After step 2 | E7: =COUNTIF(Rules!$B$2:$B$982,"P14")+COUNTIF(Rules!$B$2:$B$982,"P20") | F7: =COUNTIFS(Rules!$B$2:$B$982,"P14",Rules!$H$2:$H$982,"Built +*")+COUNTIFS(Rules!$B$2:$B$982,"P20",Rules!$H$2:$H$982,"Built +*")
A8: 3b | B8: YukthiX Service Desk: full ITSM + ESM (incident, request catalogue, problem, change / CAB, release, assets + CMDB, knowledge, SLA / OLA, portal, email / chat / WhatsApp / Teams, automation + AI, monitoring events, on-call, status page, vendors). One engine for company helpdesks (HR / IT / Admin), YukthiX's own customer support, and a standalone product | C8: M14, M08 | D8: After step 3 | E8: =COUNTIF(Rules!$B$2:$B$982,"M14")+COUNTIF(Rules!$B$2:$B$982,"M08") | F8: =COUNTIFS(Rules!$B$2:$B$982,"M14",Rules!$H$2:$H$982,"Built +*")+COUNTIFS(Rules!$B$2:$B$982,"M08",Rules!$H$2:$H$982,"Built +*")
A9: 4 | B9: Time and leave: attendance, regularisation, shifts and rosters, leave and balances, overtime | C9: M02, P03, P07 | D9: Not started | E9: =COUNTIF(Rules!$B$2:$B$982,"M02")+COUNTIF(Rules!$B$2:$B$982,"P03")+COUNTIF(Rules!$B$2:$B$982,"P07") | F9: =COUNTIFS(Rules!$B$2:$B$982,"M02",Rules!$H$2:$H$982,"Built +*")+COUNTIFS(Rules!$B$2:$B$982,"P03",Rules!$H$2:$H$982,"Built +*")+COUNTIFS(Rules!$B$2:$B$982,"P07",Rules!$H$2:$H$982,"Built +*")
A10: 5 | B10: Payroll and statutory: inputs, calculation (PF, ESI, PT, TDS), approve and lock, bank file, payslips | C10: M03, P07, P08 | D10: Not started | E10: =COUNTIF(Rules!$B$2:$B$982,"M03")+COUNTIF(Rules!$B$2:$B$982,"P07")+COUNTIF(Rules!$B$2:$B$982,"P08") | F10: =COUNTIFS(Rules!$B$2:$B$982,"M03",Rules!$H$2:$H$982,"Built +*")+COUNTIFS(Rules!$B$2:$B$982,"P07",Rules!$H$2:$H$982,"Built +*")+COUNTIFS(Rules!$B$2:$B$982,"P08",Rules!$H$2:$H$982,"Built +*")
A11: 6+ | B11: Lifecycle (onboarding, exit, F&F), expenses, performance, learning, engage, benefits, projects and timesheets, contract labour, ATS, mobile | C11: M04–M13, P-series | D11: Not started

Sheet Open work
A1: ID | B1: Area | C1: What | D1: Status (start) | E1: Status (you) | F1: Next action | G1: Owner (you) | H1: Notes (you)
A2: W-001 | B2: Step 2 · Org & employee core | C2: Parts 2c employee record, 2d access & field visibility, 2e People/Settings screens wired; then independent security review, fix every finding, push feat/yukthix-org | D2: Done | F2: PR #131 opened 7 Oct 2026 (stacked on #130); 15 review findings fixed; all suites green
A3: W-002 | B3: CI · dependencies | C3: Upgrade jest 29 → 30 and tailwind 3 → 4 so the strict audit gate (high/critical) passes on the full tree; push #129 with the security fix 377eca4c | D3: Done | F3: Jest 30 + Tailwind 4 + security patches pushed to #129 (CI passing) and merged into #130; being ported to #128
A4: W-003 | B4: Branches | C4: Merge feat/yukthix-login into feat/yukthix-workspace (#130); resolve GO-LIVE-CHECKLIST.md (login branch created its own copy) | D4: Done | F4: Merged 7 Oct 2026 (e27b49c9); checklist kept both versions (item 11 + sign-in section)
A5: W-004 | B5: Branches | C5: Merge order to main: #128 PostgreSQL → #129 login → #130 workspace → #131 step 2 | D5: Open | F5: Founder approval per PR
A6: W-005 | B6: Security review | C6: Email-first sign-in: platform staff (super admin) accounts appear as a 'YukthiX' choice in the company picker when email and password match. Staff should sign in only through the locked-down console path with hardware keys (P12) | D6: Open | F6: Decide and fix before merge of #129
A7: W-006 | B7: Security review | C7: Verified email domains are never re-checked; a lapsed domain keeps routing to SSO until removed. Add a periodic DNS re-check | D7: Open | F7: Fix in login branch
A8: W-007 | B8: UI | C8: 1,039 prototype buttons outside pay/auth have no action yet; each is wired when its backend step lands (scan-dead-buttons.mjs per wired screen must be 0) | D8: Open | F8: Per step
A9: W-008 | B9: UI · Payroll | C9: Payroll screen fixes parked by founder until the payroll backend (step 5) | D9: Parked | F9: Step 5
A10: W-009 | B10: Step 3 · Platform console | C10: Companies & lifecycle, plans & prices, shared channel accounts (move the shared Zoho SMS account here), support sessions, audit | D10: Not started | F10: After step 2
A11: W-010 | B11: Step 3b · Service Desk (M14) | C11: Full ITSM + ESM in four phases (core → ESM → ITIL → operations); one open decision: live chat transport | D11: Not started | F11: Write the detailed M14 design before the build
A12: W-011 | B12: Steps 4–6+ | C12: Time & leave (4), payroll & statutory (5), then lifecycle, expenses, performance, learning, engage, benefits, projects, contract labour, ATS, mobile | D12: Not started | F12: See Roadmap sheet
A13: W-012 | B13: Infrastructure (P13) | C13: Gap register A3: infrastructure & operations parked for the engineering team (P13 team brief) | D13: Parked | F13: Engineering team
... A16: W-015 | B16: CI · dependencies | C16: Port the same dependency fixes (security patches, Jest 30, Tailwind 4) to #128 PostgreSQL so its CI passes | D16: Done | F16: Ported to #128; CI passing

Sheet Deferred
A1: ID | B1: Step | C1: Build job | D1: Date | E1: Left out / not finished (as reported by the build job) | F1: Status (start) | G1: Status (you) | H1: Owner (you) | I1: Notes (you)
A2: D-001 | B2: UI | C2: yx-ui-merge | D2: 2026-10-06 | E2: Dead-button scan finds 1039 buttons with no action outside pay and auth (same count as the source); getting to 0 means wiring real actions across 10 modules, which I did not attempt | F2: Open (verify)
A3: D-002 | B3: UI | C3: yx-ui-merge | D3: 2026-10-06 | E3: Screenshot and axe tests (test:visual, test:a11y) were added but not run; the baselines exist for Windows only, so Linux CI would need its own | F3: Open (verify)
A4: D-003 | B4: UI | C4: yx-ui-merge | D4: 2026-10-06 | E4: Untracked docs/yukthix/GO-LIVE-CHECKLIST.md in the worktree is not from this task and was left alone | F4: Open (verify)
A5: D-004 | B5: UI | C5: yx-ui-merge | D5: 2026-10-06 | E5: Not pushed | F5: Open (verify)
A6: D-005 | B6: 0 | C6: step0-e2e | D6: 2026-10-05 | E6: Recruiter live leaderboard can stay stale (left as is, product decision needed): the push after each answer reads the deliberate 15 s shared cache (ADO #6828). If the last answers of an exam land within 15 s of the previous computation, the recruiter's board stays stale until they rejoin, because the 15 s roster tick does not re-send the leaderboard. A cheap fix is to also emit leaderboard:update from tickRoster. I did not change it because the cache is a deliberate performance trade-off. | F6: Open (verify)
A7: D-006 | B7: 0 | C7: step0-e2e | D7: 2026-10-05 | E7: e2e now runs in a single Jest worker (maxWorkers 1). Every booted app runs real BullMQ workers on one shared Redis, so parallel workers stole each other's jobs. Running suites in parallel would need per-worker queue prefixes. | F7: Open (verify)
A8: D-007 | B8: 0 | C8: step0-e2e | D8: 2026-10-05 | E8: exam-runtime e2e still prints Jest's 'did not exit one second after the test run' warning, though the run exits by itself in about 28 s. I did not trace which timer causes it. | F8: Open (verify)
A9: D-008 | B9: 0 | C9: step0-e2e | D9: 2026-10-05 | E9: Fire-and-forget analyses (for example insight generation) can still log an error after a suite's cleanup deletes the exam. It is log noise only and does not fail tests. | F9: Open (verify)
A10: D-009 | B10: 0 | C10: step0-e2e | D10: 2026-10-05 | E10: Delete the dead /uploads static file server (see security issues). | F10: Open (verify)
A11: D-010 | B11: 0 | C11: step0-postgres | D11: 2026-10-05 | E11: 21 api e2e suites (42 tests) and 1 exam-runtime e2e suite (2 tests) still fail. I left them because the code shows deliberate app changes the tests were never updated for, and rewriting the assertions would bake in product decisions without your input. Not individually traced: the AI evaluation insight cases, the webhook result left at pending, proctoring analysis stuck at processing (timeouts), the audit-log response-shape case, and the branding public-by-slug assertion. The evidence I found for the rest is: | F11: Open (verify)
A12: D-011 | B12: 0 | C12: step0-postgres | D12: 2026-10-05 | E12: Roles now have permissions the tests expect to be denied (expected 403, got 200/201 in question-bank, exam-builder, candidates, ai-jobs, exam-reporting, session-enforcement and ai-insight). | F12: Open (verify)
A13: D-012 | B13: 0 | C13: step0-postgres | D13: 2026-10-05 | E13: API responses changed shape: dashboard now requires ?window=, audit logs return {data}, and branding, compare and preview return extra fields. | F13: Open (verify)
... A106: D-105 | B106: 1 | C106: login:fix-review | D106: 2026-10-06 | E106: Some commits are grouped by area rather than one per finding, and intermediate commits may not compile on their own; the branch tip is green. | F106: Open (verify)

Sheet Go-live
A1: # | B1: Item | C1: What to do | D1: Notes | E1: Status (start) | F1: Status (you) | G1: Owner (you) | H1: Target date (you)
A2: 1 | B2: Domain | C2: Buy the app domain (e.g. app.yukthix.com) and point it at Cloudflare | D2: Needed by Turnstile, SSO redirect URLs, passkeys (WebAuthn RP ID), email sender, cookies | E2: Open
A3: 2 | B3: Cloudflare Turnstile | C3: Dashboard › Turnstile › Add widget (name "YukthiX sign-in", hostname = the domain, mode Managed). Put the secret in the API host's secret settings as TURNSTILE_SECRET_KEY and the site key as NEXT_PUBLIC_TURNSTILE_SITE_KEY | D3: Never paste the secret into chat or commit it. Local dev uses Cloudflare's always-pass test keys | E3: Open
A4: 3 | B4: New-country sign-in alerts | C4: Run the app behind Cloudflare's proxy, then set GEO_COUNTRY_HEADER=cf-ipcountry | D4: Only set it when traffic really goes through Cloudflare, or the header can be forged | E4: Open
A5: 4 | B5: SMS provider + DLT | C5: Sign up with one SMS gateway (any; the generic HTTP adapter fits MSG91, Gupshup, Kaleyra, Exotel, Textlocal; Twilio for other countries). Register YukthiX on a DLT portal: entity (company PAN/GST), sender header (6 letters), OTP template text | D5: DLT approval takes 2–7 days. Until done, codes go by email only | E5: Open
